[2024-01-15T00:12:37.240+0000] {taskinstance.py:1957} INFO - Dependencies all met for dep_context=non-requeueable deps ti=<TaskInstance: covid_dag.download_upload_data scheduled__2024-01-14T00:00:00+00:00 [queued]>
[2024-01-15T00:12:37.244+0000] {taskinstance.py:1957} INFO - Dependencies all met for dep_context=requeueable deps ti=<TaskInstance: covid_dag.download_upload_data scheduled__2024-01-14T00:00:00+00:00 [queued]>
[2024-01-15T00:12:37.244+0000] {taskinstance.py:2171} INFO - Starting attempt 1 of 1
[2024-01-15T00:12:37.263+0000] {taskinstance.py:2192} INFO - Executing <Task(PythonOperator): download_upload_data> on 2024-01-14 00:00:00+00:00
[2024-01-15T00:12:37.267+0000] {standard_task_runner.py:60} INFO - Started process 1895 to run task
[2024-01-15T00:12:37.273+0000] {standard_task_runner.py:87} INFO - Running: ['***', 'tasks', 'run', 'covid_dag', 'download_upload_data', 'scheduled__2024-01-14T00:00:00+00:00', '--job-id', '35', '--raw', '--subdir', 'DAGS_FOLDER/second_project.py', '--cfg-path', '/tmp/tmpick6p4s4']
[2024-01-15T00:12:37.275+0000] {standard_task_runner.py:88} INFO - Job 35: Subtask download_upload_data
[2024-01-15T00:12:37.313+0000] {task_command.py:423} INFO - Running <TaskInstance: covid_dag.download_upload_data scheduled__2024-01-14T00:00:00+00:00 [running]> on host 03764ffcaa3d
[2024-01-15T00:12:37.576+0000] {taskinstance.py:2481} INFO - Exporting env vars: AIRFLOW_CTX_DAG_OWNER='***' AIRFLOW_CTX_DAG_ID='covid_dag' AIRFLOW_CTX_TASK_ID='download_upload_data' AIRFLOW_CTX_EXECUTION_DATE='2024-01-14T00:00:00+00:00' AIRFLOW_CTX_TRY_NUMBER='1' AIRFLOW_CTX_DAG_RUN_ID='scheduled__2024-01-14T00:00:00+00:00'
[2024-01-15T00:12:44.428+0000] {taskinstance.py:2699} ERROR - Task failed with exception
Traceback (most recent call last):
  File "/home/airflow/.local/lib/python3.8/site-packages/airflow/models/taskinstance.py", line 433, in _execute_task
    result = execute_callable(context=context, **execute_callable_kwargs)
  File "/home/airflow/.local/lib/python3.8/site-packages/airflow/operators/python.py", line 199, in execute
    return_value = self.execute_callable()
  File "/home/airflow/.local/lib/python3.8/site-packages/airflow/operators/python.py", line 216, in execute_callable
    return self.python_callable(*self.op_args, **self.op_kwargs)
  File "/opt/airflow/dags/second_project.py", line 15, in download_upload_data
    result = wget.download(f'https://raw.githubusercontent.com/CSSEGISandData/COVID-19/master/csse_covid_19_data/csse_covid_19_daily_reports/01-{day}-2021.csv')
  File "/home/airflow/.local/lib/python3.8/site-packages/wget.py", line 526, in download
    (tmpfile, headers) = ulib.urlretrieve(binurl, tmpfile, callback)
  File "/usr/local/lib/python3.8/urllib/request.py", line 247, in urlretrieve
    with contextlib.closing(urlopen(url, data)) as fp:
  File "/usr/local/lib/python3.8/urllib/request.py", line 222, in urlopen
    return opener.open(url, data, timeout)
  File "/usr/local/lib/python3.8/urllib/request.py", line 525, in open
    response = self._open(req, data)
  File "/usr/local/lib/python3.8/urllib/request.py", line 542, in _open
    result = self._call_chain(self.handle_open, protocol, protocol +
  File "/usr/local/lib/python3.8/urllib/request.py", line 502, in _call_chain
    result = func(*args)
  File "/usr/local/lib/python3.8/urllib/request.py", line 1397, in https_open
    return self.do_open(http.client.HTTPSConnection, req,
  File "/usr/local/lib/python3.8/urllib/request.py", line 1358, in do_open
    r = h.getresponse()
  File "/usr/local/lib/python3.8/http/client.py", line 1348, in getresponse
    response.begin()
  File "/usr/local/lib/python3.8/http/client.py", line 316, in begin
    version, status, reason = self._read_status()
  File "/usr/local/lib/python3.8/http/client.py", line 285, in _read_status
    raise RemoteDisconnected("Remote end closed connection without"
http.client.RemoteDisconnected: Remote end closed connection without response
[2024-01-15T00:12:44.447+0000] {taskinstance.py:1138} INFO - Marking task as FAILED. dag_id=covid_dag, task_id=download_upload_data, execution_date=20240114T000000, start_date=20240115T001237, end_date=20240115T001244
[2024-01-15T00:12:44.462+0000] {standard_task_runner.py:107} ERROR - Failed to execute job 35 for task download_upload_data (Remote end closed connection without response; 1895)
[2024-01-15T00:12:44.492+0000] {local_task_job_runner.py:234} INFO - Task exited with return code 1
[2024-01-15T00:12:44.502+0000] {taskinstance.py:3281} INFO - 0 downstream tasks scheduled from follow-on schedule check
