[2024-01-13T00:00:00.649+0000] {taskinstance.py:1957} INFO - Dependencies all met for dep_context=non-requeueable deps ti=<TaskInstance: covid_dag.download_upload_data scheduled__2024-01-12T00:00:00+00:00 [queued]>
[2024-01-13T00:00:00.652+0000] {taskinstance.py:1957} INFO - Dependencies all met for dep_context=requeueable deps ti=<TaskInstance: covid_dag.download_upload_data scheduled__2024-01-12T00:00:00+00:00 [queued]>
[2024-01-13T00:00:00.653+0000] {taskinstance.py:2171} INFO - Starting attempt 1 of 1
[2024-01-13T00:00:00.657+0000] {taskinstance.py:2192} INFO - Executing <Task(PythonOperator): download_upload_data> on 2024-01-12 00:00:00+00:00
[2024-01-13T00:00:00.660+0000] {standard_task_runner.py:60} INFO - Started process 1122 to run task
[2024-01-13T00:00:00.662+0000] {standard_task_runner.py:87} INFO - Running: ['***', 'tasks', 'run', 'covid_dag', 'download_upload_data', 'scheduled__2024-01-12T00:00:00+00:00', '--job-id', '33', '--raw', '--subdir', 'DAGS_FOLDER/second_project.py', '--cfg-path', '/tmp/tmp7tljkehu']
[2024-01-13T00:00:00.664+0000] {standard_task_runner.py:88} INFO - Job 33: Subtask download_upload_data
[2024-01-13T00:00:00.685+0000] {task_command.py:423} INFO - Running <TaskInstance: covid_dag.download_upload_data scheduled__2024-01-12T00:00:00+00:00 [running]> on host 03764ffcaa3d
[2024-01-13T00:00:00.828+0000] {taskinstance.py:2481} INFO - Exporting env vars: AIRFLOW_CTX_DAG_OWNER='***' AIRFLOW_CTX_DAG_ID='covid_dag' AIRFLOW_CTX_TASK_ID='download_upload_data' AIRFLOW_CTX_EXECUTION_DATE='2024-01-12T00:00:00+00:00' AIRFLOW_CTX_TRY_NUMBER='1' AIRFLOW_CTX_DAG_RUN_ID='scheduled__2024-01-12T00:00:00+00:00'
[2024-01-13T00:13:38.925+0000] {taskinstance.py:2699} ERROR - Task failed with exception
Traceback (most recent call last):
  File "/home/airflow/.local/lib/python3.8/site-packages/airflow/models/taskinstance.py", line 433, in _execute_task
    result = execute_callable(context=context, **execute_callable_kwargs)
  File "/home/airflow/.local/lib/python3.8/site-packages/airflow/operators/python.py", line 199, in execute
    return_value = self.execute_callable()
  File "/home/airflow/.local/lib/python3.8/site-packages/airflow/operators/python.py", line 216, in execute_callable
    return self.python_callable(*self.op_args, **self.op_kwargs)
  File "/opt/airflow/dags/second_project.py", line 15, in download_upload_data
    result = wget.download(f'https://raw.githubusercontent.com/CSSEGISandData/COVID-19/master/csse_covid_19_data/csse_covid_19_daily_reports/01-{day}-2021.csv')
  File "/home/airflow/.local/lib/python3.8/site-packages/wget.py", line 526, in download
    (tmpfile, headers) = ulib.urlretrieve(binurl, tmpfile, callback)
  File "/usr/local/lib/python3.8/urllib/request.py", line 286, in urlretrieve
    raise ContentTooShortError(
urllib.error.ContentTooShortError: <urlopen error retrieval incomplete: got only 540672 out of 571820 bytes>
[2024-01-13T00:13:38.933+0000] {taskinstance.py:1138} INFO - Marking task as FAILED. dag_id=covid_dag, task_id=download_upload_data, execution_date=20240112T000000, start_date=20240113T000000, end_date=20240113T001338
[2024-01-13T00:13:38.939+0000] {standard_task_runner.py:107} ERROR - Failed to execute job 33 for task download_upload_data (<urlopen error retrieval incomplete: got only 540672 out of 571820 bytes>; 1122)
[2024-01-13T00:13:38.978+0000] {local_task_job_runner.py:234} INFO - Task exited with return code 1
[2024-01-13T00:13:38.986+0000] {taskinstance.py:3281} INFO - 0 downstream tasks scheduled from follow-on schedule check
