[2024-02-08T17:09:37.958+0000] {taskinstance.py:1957} INFO - Dependencies all met for dep_context=non-requeueable deps ti=<TaskInstance: covid_dag.download_upload_data manual__2024-02-08T17:09:35.142939+00:00 [queued]>
[2024-02-08T17:09:37.965+0000] {taskinstance.py:1957} INFO - Dependencies all met for dep_context=requeueable deps ti=<TaskInstance: covid_dag.download_upload_data manual__2024-02-08T17:09:35.142939+00:00 [queued]>
[2024-02-08T17:09:37.971+0000] {taskinstance.py:2171} INFO - Starting attempt 1 of 1
[2024-02-08T17:09:38.378+0000] {taskinstance.py:2192} INFO - Executing <Task(PythonOperator): download_upload_data> on 2024-02-08 17:09:35.142939+00:00
[2024-02-08T17:09:38.382+0000] {standard_task_runner.py:60} INFO - Started process 78 to run task
[2024-02-08T17:09:38.385+0000] {standard_task_runner.py:87} INFO - Running: ['***', 'tasks', 'run', 'covid_dag', 'download_upload_data', 'manual__2024-02-08T17:09:35.142939+00:00', '--job-id', '3', '--raw', '--subdir', 'DAGS_FOLDER/second_project.py', '--cfg-path', '/tmp/tmpvve52xjt']
[2024-02-08T17:09:38.387+0000] {standard_task_runner.py:88} INFO - Job 3: Subtask download_upload_data
[2024-02-08T17:09:38.423+0000] {task_command.py:423} INFO - Running <TaskInstance: covid_dag.download_upload_data manual__2024-02-08T17:09:35.142939+00:00 [running]> on host 68b80c78efd3
[2024-02-08T17:09:38.474+0000] {taskinstance.py:2481} INFO - Exporting env vars: AIRFLOW_CTX_DAG_OWNER='***' AIRFLOW_CTX_DAG_ID='covid_dag' AIRFLOW_CTX_TASK_ID='download_upload_data' AIRFLOW_CTX_EXECUTION_DATE='2024-02-08T17:09:35.142939+00:00' AIRFLOW_CTX_TRY_NUMBER='1' AIRFLOW_CTX_DAG_RUN_ID='manual__2024-02-08T17:09:35.142939+00:00'
[2024-02-08T17:09:39.349+0000] {taskinstance.py:2699} ERROR - Task failed with exception
Traceback (most recent call last):
  File "/home/airflow/.local/lib/python3.8/site-packages/sqlalchemy/engine/base.py", line 1910, in _execute_context
    self.dialect.do_execute(
  File "/home/airflow/.local/lib/python3.8/site-packages/sqlalchemy/engine/default.py", line 736, in do_execute
    cursor.execute(statement, parameters)
psycopg2.errors.UniqueViolation: duplicate key value violates unique constraint "pg_type_typname_nsp_index"
DETAIL:  Key (typname, typnamespace)=(covid19_report, 2200) already exists.


The above exception was the direct cause of the following exception:

Traceback (most recent call last):
  File "/home/airflow/.local/lib/python3.8/site-packages/airflow/models/taskinstance.py", line 433, in _execute_task
    result = execute_callable(context=context, **execute_callable_kwargs)
  File "/home/airflow/.local/lib/python3.8/site-packages/airflow/operators/python.py", line 199, in execute
    return_value = self.execute_callable()
  File "/home/airflow/.local/lib/python3.8/site-packages/airflow/operators/python.py", line 216, in execute_callable
    return self.python_callable(*self.op_args, **self.op_kwargs)
  File "/opt/airflow/dags/second_project.py", line 20, in download_upload_data
    df_final.to_sql('covid19_report', con=db, if_exists='append', index=False)
  File "/home/airflow/.local/lib/python3.8/site-packages/pandas/core/generic.py", line 2878, in to_sql
    return sql.to_sql(
  File "/home/airflow/.local/lib/python3.8/site-packages/pandas/io/sql.py", line 769, in to_sql
    return pandas_sql.to_sql(
  File "/home/airflow/.local/lib/python3.8/site-packages/pandas/io/sql.py", line 1910, in to_sql
    table = self.prep_table(
  File "/home/airflow/.local/lib/python3.8/site-packages/pandas/io/sql.py", line 1814, in prep_table
    table.create()
  File "/home/airflow/.local/lib/python3.8/site-packages/pandas/io/sql.py", line 914, in create
    self._execute_create()
  File "/home/airflow/.local/lib/python3.8/site-packages/pandas/io/sql.py", line 900, in _execute_create
    self.table.create(bind=self.pd_sql.con)
  File "/home/airflow/.local/lib/python3.8/site-packages/sqlalchemy/sql/schema.py", line 962, in create
    bind._run_ddl_visitor(ddl.SchemaGenerator, self, checkfirst=checkfirst)
  File "/home/airflow/.local/lib/python3.8/site-packages/sqlalchemy/engine/base.py", line 2221, in _run_ddl_visitor
    visitorcallable(self.dialect, self, **kwargs).traverse_single(element)
  File "/home/airflow/.local/lib/python3.8/site-packages/sqlalchemy/sql/visitors.py", line 524, in traverse_single
    return meth(obj, **kw)
  File "/home/airflow/.local/lib/python3.8/site-packages/sqlalchemy/sql/ddl.py", line 899, in visit_table
    self.connection.execute(
  File "/home/airflow/.local/lib/python3.8/site-packages/sqlalchemy/engine/base.py", line 1385, in execute
    return meth(self, multiparams, params, _EMPTY_EXECUTION_OPTS)
  File "/home/airflow/.local/lib/python3.8/site-packages/sqlalchemy/sql/ddl.py", line 80, in _execute_on_connection
    return connection._execute_ddl(
  File "/home/airflow/.local/lib/python3.8/site-packages/sqlalchemy/engine/base.py", line 1477, in _execute_ddl
    ret = self._execute_context(
  File "/home/airflow/.local/lib/python3.8/site-packages/sqlalchemy/engine/base.py", line 1953, in _execute_context
    self._handle_dbapi_exception(
  File "/home/airflow/.local/lib/python3.8/site-packages/sqlalchemy/engine/base.py", line 2134, in _handle_dbapi_exception
    util.raise_(
  File "/home/airflow/.local/lib/python3.8/site-packages/sqlalchemy/util/compat.py", line 211, in raise_
    raise exception
  File "/home/airflow/.local/lib/python3.8/site-packages/sqlalchemy/engine/base.py", line 1910, in _execute_context
    self.dialect.do_execute(
  File "/home/airflow/.local/lib/python3.8/site-packages/sqlalchemy/engine/default.py", line 736, in do_execute
    cursor.execute(statement, parameters)
sqlalchemy.exc.IntegrityError: (psycopg2.errors.UniqueViolation) duplicate key value violates unique constraint "pg_type_typname_nsp_index"
DETAIL:  Key (typname, typnamespace)=(covid19_report, 2200) already exists.

[SQL: 
CREATE TABLE covid19_report (
	"FIPS" FLOAT(53), 
	"Admin2" TEXT, 
	"Province_State" TEXT, 
	"Country_Region" TEXT, 
	"Last_Update" TEXT, 
	"Lat" FLOAT(53), 
	"Long_" FLOAT(53), 
	"Confirmed" BIGINT, 
	"Deaths" BIGINT, 
	"Recovered" BIGINT, 
	"Active" BIGINT, 
	"Combined_Key" TEXT, 
	"Incident_Rate" FLOAT(53), 
	"Case_Fatality_Ratio" FLOAT(53)
)

]
(Background on this error at: https://sqlalche.me/e/14/gkpj)
[2024-02-08T17:09:39.400+0000] {taskinstance.py:1138} INFO - Marking task as FAILED. dag_id=covid_dag, task_id=download_upload_data, execution_date=20240208T170935, start_date=20240208T170937, end_date=20240208T170939
[2024-02-08T17:09:39.421+0000] {standard_task_runner.py:107} ERROR - Failed to execute job 3 for task download_upload_data ((psycopg2.errors.UniqueViolation) duplicate key value violates unique constraint "pg_type_typname_nsp_index"
DETAIL:  Key (typname, typnamespace)=(covid19_report, 2200) already exists.

[SQL: 
CREATE TABLE covid19_report (
	"FIPS" FLOAT(53), 
	"Admin2" TEXT, 
	"Province_State" TEXT, 
	"Country_Region" TEXT, 
	"Last_Update" TEXT, 
	"Lat" FLOAT(53), 
	"Long_" FLOAT(53), 
	"Confirmed" BIGINT, 
	"Deaths" BIGINT, 
	"Recovered" BIGINT, 
	"Active" BIGINT, 
	"Combined_Key" TEXT, 
	"Incident_Rate" FLOAT(53), 
	"Case_Fatality_Ratio" FLOAT(53)
)

]
(Background on this error at: https://sqlalche.me/e/14/gkpj); 78)
[2024-02-08T17:09:39.443+0000] {local_task_job_runner.py:234} INFO - Task exited with return code 1
[2024-02-08T17:09:39.454+0000] {taskinstance.py:3281} INFO - 0 downstream tasks scheduled from follow-on schedule check
