[2024-02-08T17:09:39.822+0000] {taskinstance.py:1957} INFO - Dependencies all met for dep_context=non-requeueable deps ti=<TaskInstance: covid_dag.download_upload_data scheduled__2024-01-15T01:00:00+00:00 [queued]>
[2024-02-08T17:09:39.843+0000] {taskinstance.py:1957} INFO - Dependencies all met for dep_context=requeueable deps ti=<TaskInstance: covid_dag.download_upload_data scheduled__2024-01-15T01:00:00+00:00 [queued]>
[2024-02-08T17:09:39.844+0000] {taskinstance.py:2171} INFO - Starting attempt 1 of 1
[2024-02-08T17:09:39.868+0000] {taskinstance.py:2192} INFO - Executing <Task(PythonOperator): download_upload_data> on 2024-01-15 01:00:00+00:00
[2024-02-08T17:09:39.877+0000] {standard_task_runner.py:60} INFO - Started process 86 to run task
[2024-02-08T17:09:39.891+0000] {standard_task_runner.py:87} INFO - Running: ['***', 'tasks', 'run', 'covid_dag', 'download_upload_data', 'scheduled__2024-01-15T01:00:00+00:00', '--job-id', '5', '--raw', '--subdir', 'DAGS_FOLDER/second_project.py', '--cfg-path', '/tmp/tmp0qw40d1v']
[2024-02-08T17:09:39.895+0000] {standard_task_runner.py:88} INFO - Job 5: Subtask download_upload_data
[2024-02-08T17:09:39.988+0000] {task_command.py:423} INFO - Running <TaskInstance: covid_dag.download_upload_data scheduled__2024-01-15T01:00:00+00:00 [running]> on host 68b80c78efd3
[2024-02-08T17:09:41.472+0000] {taskinstance.py:2481} INFO - Exporting env vars: AIRFLOW_CTX_DAG_OWNER='***' AIRFLOW_CTX_DAG_ID='covid_dag' AIRFLOW_CTX_TASK_ID='download_upload_data' AIRFLOW_CTX_EXECUTION_DATE='2024-01-15T01:00:00+00:00' AIRFLOW_CTX_TRY_NUMBER='1' AIRFLOW_CTX_DAG_RUN_ID='scheduled__2024-01-15T01:00:00+00:00'
[2024-02-08T17:12:36.375+0000] {local_task_job_runner.py:302} WARNING - State of this instance has been externally set to failed. Terminating instance.
[2024-02-08T17:12:36.427+0000] {process_utils.py:131} INFO - Sending 15 to group 86. PIDs of all processes in the group: [86]
[2024-02-08T17:12:36.432+0000] {process_utils.py:86} INFO - Sending the signal 15 to group 86
[2024-02-08T17:12:36.448+0000] {taskinstance.py:2451} ERROR - Received SIGTERM. Terminating subprocesses.
[2024-02-08T17:12:36.654+0000] {process_utils.py:79} INFO - Process psutil.Process(pid=86, status='terminated', exitcode=0, started='17:09:39') (86) terminated with exit code 0
